[2025-10-31 12:19:32] Starting process for 1988-02-03 (PID: 6249)
[2025-10-31 12:19:32] DOWNLOAD START: 1988-02-03
[2025-10-31 12:19:32] Fetching fresh STAC token from Planetary Computer...
[2025-10-31 12:19:33] Opening Zarr dataset...
[2025-10-31 12:21:00] Found 24 hourly records.
[2025-10-31 12:21:00] Saving daily aggregate to data/unprocessed/daily/conus404_daily_19880203.nc
[2025-10-31 12:24:04] DOWNLOAD COMPLETE: 1988-02-03
[2025-10-31 12:24:04] VALIDATION START: data/unprocessed/daily/conus404_daily_19880203.nc
[2025-10-31 12:24:04]   QC FAIL: LAI min value -999841663821612745218903699395444736.000000 is below threshold -1
[2025-10-31 12:24:04] FAILED: File data/unprocessed/daily/conus404_daily_19880203.nc was created but FAILED validation.
[2025-10-31 12:24:04] Cleaned up corrupt file: data/unprocessed/daily/conus404_daily_19880203.nc
Traceback (most recent call last):
  File "/usr/local/other/GEOSpyD/24.3.0-0/2024-08-29/envs/py3.12/lib/python3.12/weakref.py", line 666, in _exitfunc
    f()
  File "/usr/local/other/GEOSpyD/24.3.0-0/2024-08-29/envs/py3.12/lib/python3.12/weakref.py", line 590, in __call__
    return info.func(*info.args, **(info.kwargs or {}))
           ^^^^^^^^^^^^^^^^^^^^^^^^^^^^^^^^^^^^^^^^^^^^
  File "/gpfsm/dnb33/hpmille1/venv/lib/python3.12/site-packages/fsspec/asyn.py", line 76, in sync
    raise RuntimeError("Loop is not running")
RuntimeError: Loop is not running
Traceback (most recent call last):
  File "/usr/local/other/GEOSpyD/24.3.0-0/2024-08-29/envs/py3.12/lib/python3.12/weakref.py", line 666, in _exitfunc
    f()
  File "/usr/local/other/GEOSpyD/24.3.0-0/2024-08-29/envs/py3.12/lib/python3.12/weakref.py", line 590, in __call__
    return info.func(*info.args, **(info.kwargs or {}))
           ^^^^^^^^^^^^^^^^^^^^^^^^^^^^^^^^^^^^^^^^^^^^
  File "/gpfsm/dnb33/hpmille1/venv/lib/python3.12/site-packages/fsspec/asyn.py", line 76, in sync
    raise RuntimeError("Loop is not running")
RuntimeError: Loop is not running
