[2025-10-30 11:10:37] Starting download process for 1988-11-28
[2025-10-30 11:10:37] PID: 30897
[2025-10-30 11:10:37] DOWNLOAD START: 1988-11-28
[2025-10-30 11:10:37] Memory before download: RSS=77.1MB, System=24.5%
[2025-10-30 11:10:37]   VERBOSE: Time range set: 1988-11-28 00:00:00 to 1988-11-28 23:59:59
[2025-10-30 11:10:37] Opening dataset for 1988-11-28
[2025-10-30 11:10:37]   VERBOSE: Asset Href: az://noaa/conus404.zarr
[2025-10-30 11:10:37]   VERBOSE: fsspec mapper created
[2025-10-30 11:10:38] ERROR: Failed to open dataset. Exception: Server failed to authenticate the request. Make sure the value of Authorization header is formed correctly including the signature.
RequestId:e2ba97a3-501e-0017-03af-4920b0000000
Time:2025-10-30T15:10:38.8958690Z
ErrorCode:AuthenticationFailed
authenticationerrordetail:Signature not valid in the specified time frame: Start [Wed, 29 Oct 2025 14:21:27 GMT] - Expiry [Thu, 30 Oct 2025 15:06:27 GMT] - Current [Thu, 30 Oct 2025 15:10:38 GMT]
Content: <?xml version="1.0" encoding="utf-8"?><Error><Code>AuthenticationFailed</Code><Message>Server failed to authenticate the request. Make sure the value of Authorization header is formed correctly including the signature.
RequestId:e2ba97a3-501e-0017-03af-4920b0000000
Time:2025-10-30T15:10:38.8958690Z</Message><AuthenticationErrorDetail>Signature not valid in the specified time frame: Start [Wed, 29 Oct 2025 14:21:27 GMT] - Expiry [Thu, 30 Oct 2025 15:06:27 GMT] - Current [Thu, 30 Oct 2025 15:10:38 GMT]</AuthenticationErrorDetail></Error>
[2025-10-30 11:10:38] CRITICAL: Logged failure to failed_jobs/1988-11-28.json
[2025-10-30 11:10:38] FAILED: Download unsuccessful (see errors above and failure log)
Traceback (most recent call last):
  File "/usr/local/other/GEOSpyD/24.3.0-0/2024-08-29/envs/py3.12/lib/python3.12/weakref.py", line 666, in _exitfunc
    f()
  File "/usr/local/other/GEOSpyD/24.3.0-0/2024-08-29/envs/py3.12/lib/python3.12/weakref.py", line 590, in __call__
    return info.func(*info.args, **(info.kwargs or {}))
           ^^^^^^^^^^^^^^^^^^^^^^^^^^^^^^^^^^^^^^^^^^^^
  File "/gpfsm/dnb33/hpmille1/venv/lib/python3.12/site-packages/fsspec/asyn.py", line 76, in sync
    raise RuntimeError("Loop is not running")
RuntimeError: Loop is not running
Traceback (most recent call last):
  File "/usr/local/other/GEOSpyD/24.3.0-0/2024-08-29/envs/py3.12/lib/python3.12/weakref.py", line 666, in _exitfunc
    f()
  File "/usr/local/other/GEOSpyD/24.3.0-0/2024-08-29/envs/py3.12/lib/python3.12/weakref.py", line 590, in __call__
    return info.func(*info.args, **(info.kwargs or {}))
           ^^^^^^^^^^^^^^^^^^^^^^^^^^^^^^^^^^^^^^^^^^^^
  File "/gpfsm/dnb33/hpmille1/venv/lib/python3.12/site-packages/fsspec/asyn.py", line 76, in sync
    raise RuntimeError("Loop is not running")
RuntimeError: Loop is not running
Exception ignored in: <coroutine object BaseEventLoop.create_connection at 0x7ff70012b9a0>
Traceback (most recent call last):
  File "/usr/local/other/GEOSpyD/24.3.0-0/2024-08-29/envs/py3.12/lib/python3.12/asyncio/base_events.py", line 1148, in create_connection
    transport, protocol = await self._create_connection_transport(
                          ^^^^^^^^^^^^^^^^^^^^^^^^^^^^^^^^^^^^^^^^
  File "/usr/local/other/GEOSpyD/24.3.0-0/2024-08-29/envs/py3.12/lib/python3.12/asyncio/base_events.py", line 1183, in _create_connection_transport
    transport.close()
  File "/usr/local/other/GEOSpyD/24.3.0-0/2024-08-29/envs/py3.12/lib/python3.12/asyncio/sslproto.py", line 116, in close
    self._ssl_protocol._start_shutdown()
  File "/usr/local/other/GEOSpyD/24.3.0-0/2024-08-29/envs/py3.12/lib/python3.12/asyncio/sslproto.py", line 621, in _start_shutdown
    self._abort(None)
  File "/usr/local/other/GEOSpyD/24.3.0-0/2024-08-29/envs/py3.12/lib/python3.12/asyncio/sslproto.py", line 671, in _abort
    self._transport._force_close(exc)
  File "/usr/local/other/GEOSpyD/24.3.0-0/2024-08-29/envs/py3.12/lib/python3.12/asyncio/selector_events.py", line 906, in _force_close
    self._loop.call_soon(self._call_connection_lost, exc)
  File "/usr/local/other/GEOSpyD/24.3.0-0/2024-08-29/envs/py3.12/lib/python3.12/asyncio/base_events.py", line 795, in call_soon
    self._check_closed()
  File "/usr/local/other/GEOSpyD/24.3.0-0/2024-08-29/envs/py3.12/lib/python3.12/asyncio/base_events.py", line 541, in _check_closed
    raise RuntimeError('Event loop is closed')
RuntimeError: Event loop is closed
Exception ignored in: <coroutine object BaseEventLoop.create_connection at 0x7ff70012b7f0>
Traceback (most recent call last):
  File "/usr/local/other/GEOSpyD/24.3.0-0/2024-08-29/envs/py3.12/lib/python3.12/asyncio/base_events.py", line 1148, in create_connection
    transport, protocol = await self._create_connection_transport(
                          ^^^^^^^^^^^^^^^^^^^^^^^^^^^^^^^^^^^^^^^^
  File "/usr/local/other/GEOSpyD/24.3.0-0/2024-08-29/envs/py3.12/lib/python3.12/asyncio/base_events.py", line 1183, in _create_connection_transport
    transport.close()
  File "/usr/local/other/GEOSpyD/24.3.0-0/2024-08-29/envs/py3.12/lib/python3.12/asyncio/sslproto.py", line 116, in close
    self._ssl_protocol._start_shutdown()
  File "/usr/local/other/GEOSpyD/24.3.0-0/2024-08-29/envs/py3.12/lib/python3.12/asyncio/sslproto.py", line 621, in _start_shutdown
    self._abort(None)
  File "/usr/local/other/GEOSpyD/24.3.0-0/2024-08-29/envs/py3.12/lib/python3.12/asyncio/sslproto.py", line 671, in _abort
    self._transport._force_close(exc)
  File "/usr/local/other/GEOSpyD/24.3.0-0/2024-08-29/envs/py3.12/lib/python3.12/asyncio/selector_events.py", line 906, in _force_close
    self._loop.call_soon(self._call_connection_lost, exc)
  File "/usr/local/other/GEOSpyD/24.3.0-0/2024-08-29/envs/py3.12/lib/python3.12/asyncio/base_events.py", line 795, in call_soon
    self._check_closed()
  File "/usr/local/other/GEOSpyD/24.3.0-0/2024-08-29/envs/py3.12/lib/python3.12/asyncio/base_events.py", line 541, in _check_closed
    raise RuntimeError('Event loop is closed')
RuntimeError: Event loop is closed
Exception ignored in: <coroutine object BaseEventLoop.create_connection at 0x7ff70012bb50>
Traceback (most recent call last):
  File "/usr/local/other/GEOSpyD/24.3.0-0/2024-08-29/envs/py3.12/lib/python3.12/asyncio/base_events.py", line 1148, in create_connection
    transport, protocol = await self._create_connection_transport(
                          ^^^^^^^^^^^^^^^^^^^^^^^^^^^^^^^^^^^^^^^^
  File "/usr/local/other/GEOSpyD/24.3.0-0/2024-08-29/envs/py3.12/lib/python3.12/asyncio/base_events.py", line 1183, in _create_connection_transport
    transport.close()
  File "/usr/local/other/GEOSpyD/24.3.0-0/2024-08-29/envs/py3.12/lib/python3.12/asyncio/sslproto.py", line 116, in close
    self._ssl_protocol._start_shutdown()
  File "/usr/local/other/GEOSpyD/24.3.0-0/2024-08-29/envs/py3.12/lib/python3.12/asyncio/sslproto.py", line 621, in _start_shutdown
    self._abort(None)
  File "/usr/local/other/GEOSpyD/24.3.0-0/2024-08-29/envs/py3.12/lib/python3.12/asyncio/sslproto.py", line 671, in _abort
    self._transport._force_close(exc)
  File "/usr/local/other/GEOSpyD/24.3.0-0/2024-08-29/envs/py3.12/lib/python3.12/asyncio/selector_events.py", line 906, in _force_close
    self._loop.call_soon(self._call_connection_lost, exc)
  File "/usr/local/other/GEOSpyD/24.3.0-0/2024-08-29/envs/py3.12/lib/python3.12/asyncio/base_events.py", line 795, in call_soon
    self._check_closed()
  File "/usr/local/other/GEOSpyD/24.3.0-0/2024-08-29/envs/py3.12/lib/python3.12/asyncio/base_events.py", line 541, in _check_closed
    raise RuntimeError('Event loop is closed')
RuntimeError: Event loop is closed
