[2025-10-30 11:08:04] Starting download process for 1988-05-25
[2025-10-30 11:08:04] PID: 28484
[2025-10-30 11:08:04] DOWNLOAD START: 1988-05-25
[2025-10-30 11:08:04] Memory before download: RSS=77.0MB, System=24.9%
[2025-10-30 11:08:04]   VERBOSE: Time range set: 1988-05-25 00:00:00 to 1988-05-25 23:59:59
[2025-10-30 11:08:04] Opening dataset for 1988-05-25
[2025-10-30 11:08:04]   VERBOSE: Asset Href: az://noaa/conus404.zarr
[2025-10-30 11:08:04]   VERBOSE: fsspec mapper created
[2025-10-30 11:08:05] ERROR: Failed to open dataset. Exception: Server failed to authenticate the request. Make sure the value of Authorization header is formed correctly including the signature.
RequestId:9601d299-001e-001a-35ae-49e864000000
Time:2025-10-30T15:08:05.9553248Z
ErrorCode:AuthenticationFailed
authenticationerrordetail:Signature not valid in the specified time frame: Start [Wed, 29 Oct 2025 14:21:27 GMT] - Expiry [Thu, 30 Oct 2025 15:06:27 GMT] - Current [Thu, 30 Oct 2025 15:08:05 GMT]
Content: <?xml version="1.0" encoding="utf-8"?><Error><Code>AuthenticationFailed</Code><Message>Server failed to authenticate the request. Make sure the value of Authorization header is formed correctly including the signature.
RequestId:9601d299-001e-001a-35ae-49e864000000
Time:2025-10-30T15:08:05.9553248Z</Message><AuthenticationErrorDetail>Signature not valid in the specified time frame: Start [Wed, 29 Oct 2025 14:21:27 GMT] - Expiry [Thu, 30 Oct 2025 15:06:27 GMT] - Current [Thu, 30 Oct 2025 15:08:05 GMT]</AuthenticationErrorDetail></Error>
[2025-10-30 11:08:05] CRITICAL: Logged failure to failed_jobs/1988-05-25.json
[2025-10-30 11:08:05] FAILED: Download unsuccessful (see errors above and failure log)
Traceback (most recent call last):
  File "/usr/local/other/GEOSpyD/24.3.0-0/2024-08-29/envs/py3.12/lib/python3.12/weakref.py", line 666, in _exitfunc
    f()
  File "/usr/local/other/GEOSpyD/24.3.0-0/2024-08-29/envs/py3.12/lib/python3.12/weakref.py", line 590, in __call__
    return info.func(*info.args, **(info.kwargs or {}))
           ^^^^^^^^^^^^^^^^^^^^^^^^^^^^^^^^^^^^^^^^^^^^
  File "/gpfsm/dnb33/hpmille1/venv/lib/python3.12/site-packages/fsspec/asyn.py", line 76, in sync
    raise RuntimeError("Loop is not running")
RuntimeError: Loop is not running
Traceback (most recent call last):
  File "/usr/local/other/GEOSpyD/24.3.0-0/2024-08-29/envs/py3.12/lib/python3.12/weakref.py", line 666, in _exitfunc
    f()
  File "/usr/local/other/GEOSpyD/24.3.0-0/2024-08-29/envs/py3.12/lib/python3.12/weakref.py", line 590, in __call__
    return info.func(*info.args, **(info.kwargs or {}))
           ^^^^^^^^^^^^^^^^^^^^^^^^^^^^^^^^^^^^^^^^^^^^
  File "/gpfsm/dnb33/hpmille1/venv/lib/python3.12/site-packages/fsspec/asyn.py", line 76, in sync
    raise RuntimeError("Loop is not running")
RuntimeError: Loop is not running
