[2025-10-30 11:10:37] Starting download process for 1988-11-30
[2025-10-30 11:10:37] PID: 30899
[2025-10-30 11:10:37] DOWNLOAD START: 1988-11-30
[2025-10-30 11:10:37] Memory before download: RSS=77.0MB, System=24.5%
[2025-10-30 11:10:37]   VERBOSE: Time range set: 1988-11-30 00:00:00 to 1988-11-30 23:59:59
[2025-10-30 11:10:37] Opening dataset for 1988-11-30
[2025-10-30 11:10:37]   VERBOSE: Asset Href: az://noaa/conus404.zarr
[2025-10-30 11:10:37]   VERBOSE: fsspec mapper created
[2025-10-30 11:10:39] ERROR: Failed to open dataset. Exception: Server failed to authenticate the request. Make sure the value of Authorization header is formed correctly including the signature.
RequestId:be458f25-a01e-0003-12af-4968df000000
Time:2025-10-30T15:10:39.0149723Z
ErrorCode:AuthenticationFailed
authenticationerrordetail:Signature not valid in the specified time frame: Start [Wed, 29 Oct 2025 14:21:27 GMT] - Expiry [Thu, 30 Oct 2025 15:06:27 GMT] - Current [Thu, 30 Oct 2025 15:10:39 GMT]
Content: <?xml version="1.0" encoding="utf-8"?><Error><Code>AuthenticationFailed</Code><Message>Server failed to authenticate the request. Make sure the value of Authorization header is formed correctly including the signature.
RequestId:be458f25-a01e-0003-12af-4968df000000
Time:2025-10-30T15:10:39.0149723Z</Message><AuthenticationErrorDetail>Signature not valid in the specified time frame: Start [Wed, 29 Oct 2025 14:21:27 GMT] - Expiry [Thu, 30 Oct 2025 15:06:27 GMT] - Current [Thu, 30 Oct 2025 15:10:39 GMT]</AuthenticationErrorDetail></Error>
[2025-10-30 11:10:39] CRITICAL: Logged failure to failed_jobs/1988-11-30.json
[2025-10-30 11:10:39] FAILED: Download unsuccessful (see errors above and failure log)
Traceback (most recent call last):
  File "/usr/local/other/GEOSpyD/24.3.0-0/2024-08-29/envs/py3.12/lib/python3.12/weakref.py", line 666, in _exitfunc
    f()
  File "/usr/local/other/GEOSpyD/24.3.0-0/2024-08-29/envs/py3.12/lib/python3.12/weakref.py", line 590, in __call__
    return info.func(*info.args, **(info.kwargs or {}))
           ^^^^^^^^^^^^^^^^^^^^^^^^^^^^^^^^^^^^^^^^^^^^
  File "/gpfsm/dnb33/hpmille1/venv/lib/python3.12/site-packages/fsspec/asyn.py", line 76, in sync
    raise RuntimeError("Loop is not running")
RuntimeError: Loop is not running
Traceback (most recent call last):
  File "/usr/local/other/GEOSpyD/24.3.0-0/2024-08-29/envs/py3.12/lib/python3.12/weakref.py", line 666, in _exitfunc
    f()
  File "/usr/local/other/GEOSpyD/24.3.0-0/2024-08-29/envs/py3.12/lib/python3.12/weakref.py", line 590, in __call__
    return info.func(*info.args, **(info.kwargs or {}))
           ^^^^^^^^^^^^^^^^^^^^^^^^^^^^^^^^^^^^^^^^^^^^
  File "/gpfsm/dnb33/hpmille1/venv/lib/python3.12/site-packages/fsspec/asyn.py", line 76, in sync
    raise RuntimeError("Loop is not running")
RuntimeError: Loop is not running
Task exception was never retrieved
future: <Task finished name='Task-3' coro=<StorePath.get() done, defined at /gpfsm/dnb33/hpmille1/venv/lib/python3.12/site-packages/zarr/storage/_common.py:146> exception=ClientAuthenticationError('Server failed to authenticate the request. Make sure the value of Authorization header is formed correctly including the signature.\nRequestId:7a29dd0e-e01e-003d-1daf-49ffa0000000\nTime:2025-10-30T15:10:39.0153554Z\nErrorCode:AuthenticationFailed\nauthenticationerrordetail:Signature not valid in the specified time frame: Start [Wed, 29 Oct 2025 14:21:27 GMT] - Expiry [Thu, 30 Oct 2025 15:06:27 GMT] - Current [Thu, 30 Oct 2025 15:10:39 GMT]')>
Traceback (most recent call last):
  File "/gpfsm/dnb33/hpmille1/venv/lib/python3.12/site-packages/zarr/storage/_common.py", line 168, in get
    return await self.store.get(self.path, prototype=prototype, byte_range=byte_range)
           ^^^^^^^^^^^^^^^^^^^^^^^^^^^^^^^^^^^^^^^^^^^^^^^^^^^^^^^^^^^^^^^^^^^^^^^^^^^
  File "/gpfsm/dnb33/hpmille1/venv/lib/python3.12/site-packages/zarr/storage/_fsspec.py", line 299, in get
    value = prototype.buffer.from_bytes(await self.fs._cat_file(path))
                                        ^^^^^^^^^^^^^^^^^^^^^^^^^^^^^
  File "/gpfsm/dnb33/hpmille1/venv/lib/python3.12/site-packages/adlfs/spec.py", line 1500, in _cat_file
    stream = await bc.download_blob(
             ^^^^^^^^^^^^^^^^^^^^^^^
  File "/gpfsm/dnb33/hpmille1/venv/lib/python3.12/site-packages/azure/core/tracing/decorator_async.py", line 119, in wrapper_use_tracer
    return await func(*args, **kwargs)
           ^^^^^^^^^^^^^^^^^^^^^^^^^^^
  File "/gpfsm/dnb33/hpmille1/venv/lib/python3.12/site-packages/azure/storage/blob/aio/_blob_client_async.py", line 793, in download_blob
    await downloader._setup()  # pylint: disable=protected-access
    ^^^^^^^^^^^^^^^^^^^^^^^^^
  File "/gpfsm/dnb33/hpmille1/venv/lib/python3.12/site-packages/azure/storage/blob/aio/_download_async.py", line 332, in _setup
    self._response = await self._initial_request()
                     ^^^^^^^^^^^^^^^^^^^^^^^^^^^^^
  File "/gpfsm/dnb33/hpmille1/venv/lib/python3.12/site-packages/azure/storage/blob/aio/_download_async.py", line 414, in _initial_request
    process_storage_error(error)
  File "/gpfsm/dnb33/hpmille1/venv/lib/python3.12/site-packages/azure/storage/blob/_shared/response_handlers.py", line 195, in process_storage_error
    exec("raise error from None")  # pylint: disable=exec-used # nosec
    ^^^^^^^^^^^^^^^^^^^^^^^^^^^^^
  File "<string>", line 1, in <module>
azure.core.exceptions.ClientAuthenticationError: Server failed to authenticate the request. Make sure the value of Authorization header is formed correctly including the signature.
RequestId:7a29dd0e-e01e-003d-1daf-49ffa0000000
Time:2025-10-30T15:10:39.0153554Z
ErrorCode:AuthenticationFailed
authenticationerrordetail:Signature not valid in the specified time frame: Start [Wed, 29 Oct 2025 14:21:27 GMT] - Expiry [Thu, 30 Oct 2025 15:06:27 GMT] - Current [Thu, 30 Oct 2025 15:10:39 GMT]
Content: <?xml version="1.0" encoding="utf-8"?><Error><Code>AuthenticationFailed</Code><Message>Server failed to authenticate the request. Make sure the value of Authorization header is formed correctly including the signature.
RequestId:7a29dd0e-e01e-003d-1daf-49ffa0000000
Time:2025-10-30T15:10:39.0153554Z</Message><AuthenticationErrorDetail>Signature not valid in the specified time frame: Start [Wed, 29 Oct 2025 14:21:27 GMT] - Expiry [Thu, 30 Oct 2025 15:06:27 GMT] - Current [Thu, 30 Oct 2025 15:10:39 GMT]</AuthenticationErrorDetail></Error>
