[2025-10-30 03:06:56] Starting download process for 1988-12-14
[2025-10-30 03:06:56] PID: 32004
[2025-10-30 03:06:56] DOWNLOAD START: 1988-12-14
[2025-10-30 03:06:56] Memory before download: RSS=77.0MB, System=25.1%
[2025-10-30 03:06:56]   VERBOSE: Time range set: 1988-12-14 00:00:00 to 1988-12-14 23:59:59
[2025-10-30 03:06:56] Opening dataset for 1988-12-14
[2025-10-30 03:06:56]   VERBOSE: Asset Href: az://noaa/conus404.zarr
[2025-10-30 03:06:56]   VERBOSE: fsspec mapper created
[2025-10-30 03:06:57] ERROR: Failed to open dataset. Exception: Server failed to authenticate the request. Make sure the value of Authorization header is formed correctly including the signature.
RequestId:d78a601f-001e-001a-016b-49e864000000
Time:2025-10-30T07:06:57.4546685Z
ErrorCode:AuthenticationFailed
authenticationerrordetail:Signature not valid in the specified time frame: Start [Wed, 29 Oct 2025 06:18:06 GMT] - Expiry [Thu, 30 Oct 2025 07:03:06 GMT] - Current [Thu, 30 Oct 2025 07:06:57 GMT]
Content: <?xml version="1.0" encoding="utf-8"?><Error><Code>AuthenticationFailed</Code><Message>Server failed to authenticate the request. Make sure the value of Authorization header is formed correctly including the signature.
RequestId:d78a601f-001e-001a-016b-49e864000000
Time:2025-10-30T07:06:57.4546685Z</Message><AuthenticationErrorDetail>Signature not valid in the specified time frame: Start [Wed, 29 Oct 2025 06:18:06 GMT] - Expiry [Thu, 30 Oct 2025 07:03:06 GMT] - Current [Thu, 30 Oct 2025 07:06:57 GMT]</AuthenticationErrorDetail></Error>
[2025-10-30 03:06:57] CRITICAL: Logged failure to failed_jobs/1988-12-14.json
[2025-10-30 03:06:57] FAILED: Download unsuccessful (see errors above and failure log)
Traceback (most recent call last):
  File "/usr/local/other/GEOSpyD/24.3.0-0/2024-08-29/envs/py3.12/lib/python3.12/weakref.py", line 666, in _exitfunc
    f()
  File "/usr/local/other/GEOSpyD/24.3.0-0/2024-08-29/envs/py3.12/lib/python3.12/weakref.py", line 590, in __call__
    return info.func(*info.args, **(info.kwargs or {}))
           ^^^^^^^^^^^^^^^^^^^^^^^^^^^^^^^^^^^^^^^^^^^^
  File "/gpfsm/dnb33/hpmille1/venv/lib/python3.12/site-packages/fsspec/asyn.py", line 76, in sync
    raise RuntimeError("Loop is not running")
RuntimeError: Loop is not running
Traceback (most recent call last):
  File "/usr/local/other/GEOSpyD/24.3.0-0/2024-08-29/envs/py3.12/lib/python3.12/weakref.py", line 666, in _exitfunc
    f()
  File "/usr/local/other/GEOSpyD/24.3.0-0/2024-08-29/envs/py3.12/lib/python3.12/weakref.py", line 590, in __call__
    return info.func(*info.args, **(info.kwargs or {}))
           ^^^^^^^^^^^^^^^^^^^^^^^^^^^^^^^^^^^^^^^^^^^^
  File "/gpfsm/dnb33/hpmille1/venv/lib/python3.12/site-packages/fsspec/asyn.py", line 76, in sync
    raise RuntimeError("Loop is not running")
RuntimeError: Loop is not running
