[2025-10-30 03:06:31] Starting download process for 1988-11-04
[2025-10-30 03:06:31] PID: 31613
[2025-10-30 03:06:31] DOWNLOAD START: 1988-11-04
[2025-10-30 03:06:31] Memory before download: RSS=77.1MB, System=25.0%
[2025-10-30 03:06:31]   VERBOSE: Time range set: 1988-11-04 00:00:00 to 1988-11-04 23:59:59
[2025-10-30 03:06:31] Opening dataset for 1988-11-04
[2025-10-30 03:06:31]   VERBOSE: Asset Href: az://noaa/conus404.zarr
[2025-10-30 03:06:31]   VERBOSE: fsspec mapper created
[2025-10-30 03:06:32] ERROR: Failed to open dataset. Exception: Server failed to authenticate the request. Make sure the value of Authorization header is formed correctly including the signature.
RequestId:95581b52-901e-0055-1a6b-499930000000
Time:2025-10-30T07:06:32.4821641Z
ErrorCode:AuthenticationFailed
authenticationerrordetail:Signature not valid in the specified time frame: Start [Wed, 29 Oct 2025 06:18:06 GMT] - Expiry [Thu, 30 Oct 2025 07:03:06 GMT] - Current [Thu, 30 Oct 2025 07:06:32 GMT]
Content: <?xml version="1.0" encoding="utf-8"?><Error><Code>AuthenticationFailed</Code><Message>Server failed to authenticate the request. Make sure the value of Authorization header is formed correctly including the signature.
RequestId:95581b52-901e-0055-1a6b-499930000000
Time:2025-10-30T07:06:32.4821641Z</Message><AuthenticationErrorDetail>Signature not valid in the specified time frame: Start [Wed, 29 Oct 2025 06:18:06 GMT] - Expiry [Thu, 30 Oct 2025 07:03:06 GMT] - Current [Thu, 30 Oct 2025 07:06:32 GMT]</AuthenticationErrorDetail></Error>
[2025-10-30 03:06:32] CRITICAL: Logged failure to failed_jobs/1988-11-04.json
[2025-10-30 03:06:32] FAILED: Download unsuccessful (see errors above and failure log)
Traceback (most recent call last):
  File "/usr/local/other/GEOSpyD/24.3.0-0/2024-08-29/envs/py3.12/lib/python3.12/weakref.py", line 666, in _exitfunc
    f()
  File "/usr/local/other/GEOSpyD/24.3.0-0/2024-08-29/envs/py3.12/lib/python3.12/weakref.py", line 590, in __call__
    return info.func(*info.args, **(info.kwargs or {}))
           ^^^^^^^^^^^^^^^^^^^^^^^^^^^^^^^^^^^^^^^^^^^^
  File "/gpfsm/dnb33/hpmille1/venv/lib/python3.12/site-packages/fsspec/asyn.py", line 76, in sync
    raise RuntimeError("Loop is not running")
RuntimeError: Loop is not running
Traceback (most recent call last):
  File "/usr/local/other/GEOSpyD/24.3.0-0/2024-08-29/envs/py3.12/lib/python3.12/weakref.py", line 666, in _exitfunc
    f()
  File "/usr/local/other/GEOSpyD/24.3.0-0/2024-08-29/envs/py3.12/lib/python3.12/weakref.py", line 590, in __call__
    return info.func(*info.args, **(info.kwargs or {}))
           ^^^^^^^^^^^^^^^^^^^^^^^^^^^^^^^^^^^^^^^^^^^^
  File "/gpfsm/dnb33/hpmille1/venv/lib/python3.12/site-packages/fsspec/asyn.py", line 76, in sync
    raise RuntimeError("Loop is not running")
RuntimeError: Loop is not running
Exception ignored in: <coroutine object BaseEventLoop.create_connection at 0x7f2308806f80>
Traceback (most recent call last):
  File "/usr/local/other/GEOSpyD/24.3.0-0/2024-08-29/envs/py3.12/lib/python3.12/asyncio/base_events.py", line 1148, in create_connection
    transport, protocol = await self._create_connection_transport(
                          ^^^^^^^^^^^^^^^^^^^^^^^^^^^^^^^^^^^^^^^^
  File "/usr/local/other/GEOSpyD/24.3.0-0/2024-08-29/envs/py3.12/lib/python3.12/asyncio/base_events.py", line 1183, in _create_connection_transport
    transport.close()
  File "/usr/local/other/GEOSpyD/24.3.0-0/2024-08-29/envs/py3.12/lib/python3.12/asyncio/sslproto.py", line 116, in close
    self._ssl_protocol._start_shutdown()
  File "/usr/local/other/GEOSpyD/24.3.0-0/2024-08-29/envs/py3.12/lib/python3.12/asyncio/sslproto.py", line 621, in _start_shutdown
    self._abort(None)
  File "/usr/local/other/GEOSpyD/24.3.0-0/2024-08-29/envs/py3.12/lib/python3.12/asyncio/sslproto.py", line 671, in _abort
    self._transport._force_close(exc)
  File "/usr/local/other/GEOSpyD/24.3.0-0/2024-08-29/envs/py3.12/lib/python3.12/asyncio/selector_events.py", line 906, in _force_close
    self._loop.call_soon(self._call_connection_lost, exc)
  File "/usr/local/other/GEOSpyD/24.3.0-0/2024-08-29/envs/py3.12/lib/python3.12/asyncio/base_events.py", line 795, in call_soon
    self._check_closed()
  File "/usr/local/other/GEOSpyD/24.3.0-0/2024-08-29/envs/py3.12/lib/python3.12/asyncio/base_events.py", line 541, in _check_closed
    raise RuntimeError('Event loop is closed')
RuntimeError: Event loop is closed
